2024-09-12 17:42:19,416 - Failed to import data into datedimension: (pymysql.err.OperationalError) (1045, "Access denied for user 'username'@'localhost' (using password: YES)")
(Background on this error at: https://sqlalche.me/e/20/e3q8)
2024-09-12 17:42:19,432 - Failed to import data into countrydimension: (pymysql.err.OperationalError) (1045, "Access denied for user 'username'@'localhost' (using password: YES)")
(Background on this error at: https://sqlalche.me/e/20/e3q8)
2024-09-12 17:42:19,432 - Failed to import data into detailedlocationdimension: (pymysql.err.OperationalError) (1045, "Access denied for user 'username'@'localhost' (using password: YES)")
(Background on this error at: https://sqlalche.me/e/20/e3q8)
2024-09-12 17:42:19,432 - Failed to import data into networktrafficdimension: (pymysql.err.OperationalError) (1045, "Access denied for user 'username'@'localhost' (using password: YES)")
(Background on this error at: https://sqlalche.me/e/20/e3q8)
2024-09-12 17:42:19,432 - Failed to import data into companydimension: (pymysql.err.OperationalError) (1045, "Access denied for user 'username'@'localhost' (using password: YES)")
(Background on this error at: https://sqlalche.me/e/20/e3q8)
2024-09-12 17:42:19,432 - Failed to import data into devicedimension: (pymysql.err.OperationalError) (1045, "Access denied for user 'username'@'localhost' (using password: YES)")
(Background on this error at: https://sqlalche.me/e/20/e3q8)
2024-09-12 17:42:19,432 - Failed to import data into individualcyberattacksfact: (pymysql.err.OperationalError) (1045, "Access denied for user 'username'@'localhost' (using password: YES)")
(Background on this error at: https://sqlalche.me/e/20/e3q8)
2024-09-12 17:42:19,432 - Failed to import data into companiescyberattacksfact: (pymysql.err.OperationalError) (1045, "Access denied for user 'username'@'localhost' (using password: YES)")
(Background on this error at: https://sqlalche.me/e/20/e3q8)
2024-09-12 17:42:19,432 - Failed to import data into activeonlineusersfact: (pymysql.err.OperationalError) (1045, "Access denied for user 'username'@'localhost' (using password: YES)")
(Background on this error at: https://sqlalche.me/e/20/e3q8)
2024-09-12 17:43:37,141 - Failed to import data into datedimension: Not an executable object: 'SELECT COUNT(*) FROM datedimension'
2024-09-12 17:43:37,141 - Failed to import data into countrydimension: Not an executable object: 'SELECT COUNT(*) FROM countrydimension'
2024-09-12 17:43:38,177 - Failed to import data into detailedlocationdimension: Not an executable object: 'SELECT COUNT(*) FROM detailedlocationdimension'
2024-09-12 17:43:39,290 - Failed to import data into networktrafficdimension: Not an executable object: 'SELECT COUNT(*) FROM networktrafficdimension'
2024-09-12 17:43:39,902 - Failed to import data into companydimension: Not an executable object: 'SELECT COUNT(*) FROM companydimension'
2024-09-12 17:43:39,913 - Failed to import data into devicedimension: Not an executable object: 'SELECT COUNT(*) FROM devicedimension'
2024-09-12 17:43:42,804 - Failed to import data into individualcyberattacksfact: Not an executable object: 'SELECT COUNT(*) FROM individualcyberattacksfact'
2024-09-12 17:43:44,091 - Failed to import data into companiescyberattacksfact: Not an executable object: 'SELECT COUNT(*) FROM companiescyberattacksfact'
2024-09-12 17:43:44,138 - Failed to import data into activeonlineusersfact: Not an executable object: 'SELECT COUNT(*) FROM activeonlineusersfact'
